Workbook
Name _Hlk139297106: Правило!$C$29
Name _Hlk139297106: Протокол!$C$29

Sheet Протокол
I3: Общество с ограниченной ответственностью «А-Профит»
I4: (ООО «А-Профит»)
I5: Адрес места нахождения юридического лица:
I6: 690074, Россия, Приморский край, г. Владивосток, ул. Снеговая, д. 64, офис 1
I7: Тел.: 89240037850, e-mail: a_profit_lab@mail.ru
I9: Испытательная лаборатория ООО «А-Профит»
I10: (ООО «А-Профит»)
I11: Адреса мест осуществления деятельности:
I12: 690074, Россия, Приморский край, г. Владивосток, ул. Снеговая, д. 64
I13: Тел.: 89240037850, e-mail: a_profit_lab@mail.ru
M16: УТВЕРЖДАЮ
M18: Руководитель ИЛ ООО «А-Профит»
O19: А.Г. Луговой
M20: Подпись | O20: И.О. Фамилия
M21: =L28 -> 46132
I22: М.П.
G28: Протокол № | I28: РАБ01 | K28: от | L28: 46132 | N28: г.
C29: идентификации, технической экспертизы конструкции, исследований, испытаний и измерений транспортного средства на соответствия предъявляемым требованиям ТР ТС 018/2011 к Единичным транспортным средствам
H73: Результаты исследований, испытаний и измерений относятся только к образцу (объекту), предоставленному заказчиком.
H74: Результаты исследований, испытаний и измерений относятся только к образцу (объекту), прошедшему исследования,
H75: испытания и измерения в испытательной лаборатории ООО «А-Профит».
H76: Протокол не может быть частично воспроизведен без письменного разрешения лаборатории.
H77: Испытательная лаборатория (центр) несет ответственность за всю информацию, предоставленную в протоколе
H78: испытаний, за исключением случаев, когда информация предоставлена заказчиком.
A80: Протокол идентификации, технической экспертизы конструкции, исследований, испытаний и измерений транспортного средства на соответствия предъявляемым требованиям
E81: ТР ТС 018/2011 к Единичным транспортным средствам № | J81: =I28 -> РАБ01 | L81: от | M81: =L28 -> 46132
I83: 1. ОБЪЕКТ ИСПЫТАНИЙ
B84: Таблица 1.1 Общие сведения
A85: Наименование образца испытаний (идентификация объекта, поступившего на испытания: марка, тип/обозначение, заводской номер, другая уникальная идентифицирующая информация) | F85: Транспортное средство:
F86: Марка | K86: Kia
F87: коммерческое название | K87: Rio
F88: тип | K88: CB41
F89: Индефикационный номер (VIN) или серийный (заводской) номер | K89: Z94CB41BBHR378731
F90: Гос. Номер | K90: С360СС 25RUS
F91: Категория | K91: М1
A92: Наименование и контактные данные заказчика* (для юридических лиц указывают наименование, юридический адрес и фактический адрес места осуществления деятельности; для ИП указывают инициалы, фамилию, адрес регистрации; для физического лица указывают инициалы, фамилию, почтовый адрес) | F92: ООО «А-Профит» Адрес места нахождения юридического лица: 690074, Россия, Приморский край, г. Владивосток, ул. Снеговая, д. 64, офис 1 Адреса мест осуществления деятельности: 690074, Россия, Приморский край, г. Владивосток, ул. Снеговая, д. 64
A97: Наименование и адрес изготовителя (юридический адрес и фактический адрес места осуществления деятельности) | F97: Изготовитель: ООО "Хендэ Мотор Мануфактуринг Рус" Адрес юридический и фактический: 197701, г. Санкт-Петербург, Курортный район, г. Сестрорецк, Левашовское шоссе, д.20, лит А, Российская Федерация Сборочный завод: ООО "Хендэ Мотор Мануфактуринг Рус" Адрес юридический и фактический: 197701, г. Санкт-Петербург, Курортный район, г. Сестрорецк, Левашовское шоссе, д.20, лит А, Российская Федерация
A100: Данные об отборе образца | F100: Образец предоставлен заказчиком, ИЛ не несет ответственности за данные отбора образца
A102: Дата получения образца | F102: =L28 -> 46132
A103: Дата(ы) начала и окончания испытаний | F103: =L28 -> 46132
...

Sheet Расчет
B1: 1. Расчет неопределенности измерений угла наклона государственного регистрационного знака и высоты от опорной плоскости верхнего края государственного регистрационного знака
B3: Используемое оборудование
B4: Заводской № | D4: Модель | G4: Ед. изм. | H4: Пределы допускаемой абсолютной погрешности | K4: Примечание
B5: 9405 | D5: Угломер маятниковый З УРИ-М | G5: градус | H5: ± | I5: 1
B6: 4-24020385 | D6: Угломер с нониусом Micron, мождификация УНЛ-360 | G6: минута | H6: ± | I6: 5
G7: мм | H7: ± | I7: 0.15 | K7: Миллимитровый интервал
B8: 2438 | D8: Рулетка RGK R-5 | G8: мм | H8: ± | I8: 0.2 | K8: сантимитровый интервал
G9: мм | H9: ± | I9: 0.3 | K9: дециметровый интервал
G10: мм | H10: ± | I10: (0,30+0,15(L-1)) | K10: отрезок шкалы 1 м и более
B11: Результаты измерений
B12: Угол между плоскостью государственного регистрационного знака и продольной плоскостью симметрии ТС, град | H12: Передний | I12: Задний
H13: =Вводные!H2 -> 90 | I13: =Вводные!I2 -> 90
B14: Угол между плоскостью государственного регистрационного знака и опорной поверхностью, град | H14: Передний | I14: Задний
H15: =Вводные!H4 -> 90 | I15: =Вводные!I4 -> 90
B16: Высота от опорной плоскости верхнего края государственного регистрационного знака, мм | H16: Передний | I16: Задний
H17: =Вводные!H6 -> 302 | I17: =Вводные!I6 -> 600
B18: Высота от опорной плоскости нижнего края государственного регистрационного знака, мм | H18: Передний | I18: Задний
H19: =Вводные!H8 -> 500 | I19: =Вводные!I8 -> 500
B20: 1.1. Расчет неопределенности измерений угла между плоскостью государственного регистрационного знака и продольной плоскостью симметрии ТС
B21: Суммарная стандартная неопределенность измерения угла между плоскостью государственного регистрационного знака и продольной плоскостью симметрии ТС:
E22: формула 10 ГОСТ 34100.3-2017/ISO/IEC Guide 98-3:2008
B24: где | D24: стандартная неопределенность измерения угла между плоскостью государственного регистрационного знака и продольной плоскостью симметрии ТС, оцененная по типу А
D25: стандартная неопределенность измерения угла между плоскостью государственного регистрационного знака и продольной плоскостью симметрии ТС, оцененная по типу B
B27: Стандартная неопределенность измерения угла между плоскостью государственного регистрационного знака и продольной плоскостью симметрии ТС, оцененная по типу B
D28: где | E28: = | F28: =I6/60 -> 0.083333333 | G28: ˚ | H28: абсолютная погрешность угломера с нониусом 4УМ
C30: = | D30: =F28/(3^0.5) -> 0.048112522 | E30: ˚
B32: Бюджет неопределенности
B33: Формула для расчета определяемой величины:
B34: где | D34: результат измерения угла между плоскостью государственного регистрационного знака и продольной плоскостью симметрии ТС
D35: поправка на погрешность средства измерений
B36: Бюджет неопределенности для измерения угла между плоскостью переднего государственного регистрационного знака и продольной плоскостью симметрии ТС
B37: Входная величина | D37: Оценка входной величины, градусы | F37: Стандартная неопределенность, градусы | H37: Распределение | J37: Коэффициент чувствительности | L37: Вклад в неопределенность | N37: Процент вклада, %
D38: =H13 -> 90 | F38: 0 | H38: нормальное | J38: 1 | L38: 0 | N38: 0
D39: 0 | F39: =D30 -> 0.048112522 | H39: прямоугольное | J39: 1 | L39: =F39 -> 0.048112522 | N39: 100
D40: =D38 -> 90 | F40: =F39 -> 0.048112522 | N40: 100
B42: Бюджет неопределенности для измерения угла между плоскостью заднего государственного регистрационного знака и продольной плоскостью симметрии ТС
B43: Входная величина | D43: Оценка входной величины, градусы | F43: Стандартная неопределенность, градусы | H43: Распределение | J43: Коэффициент чувствительности | L43: Вклад в неопределенность | N43: Процент вклада, %
D44: =I13 -> 90 | F44: 0 | H44: нормальное | J44: 1 | L44: 0 | N44: 0
D45: 0 | F45: =D30 -> 0.048112522 | H45: прямоугольное | J45: 1 | L45: =F45 -> 0.048112522 | N45: 100
D46: =D44 -> 90 | F46: =F45 -> 0.048112522 | N46: 100
...

Sheet Вводные
A1: п. А 1.2.2 прил. А ГОСТ 33670-2015 | B1: Угол между плоскостью государственного регистрационного знака и продольной плоскостью симметрии ТС, град | H1: Передний | I1: Задний | S1: мин | T1: макс
H2: 90 | I2: 90 | S2: 88 | T2: 92
B3: Угол между плоскостью государственного регистрационного знака и опорной поверхностью, град | H3: Передний | I3: Задний
H4: 90 | I4: 90 | S4: 62 | T4: 118
A5: п. А 1.2.3 прил. А ГОСТ 33670-2015 | B5: Высота от опорной плоскости верхнего края государственного регистрационного знака, мм | H5: Передний | I5: Задний
H6: 302 | I6: 600 | S6: 298 | T6: 1198
B7: Высота от опорной плоскости нижнего края государственного регистрационного знака, мм | H7: Передний | I7: Задний
H8: 500 | I8: 500 | S8: 298 | T8: 1198
A9: п. А 5.1.1.3 прил. А ГОСТ 33670-2015 | B9: Усилие на органе управления рабочей тормозной системы | H9: Ось 1 | I9: Ось 2 | J9: ед изм
H10: 490 | I10: 490 | J10: Н | S10: 10 | T10: 490
A11: п. А 5.1.1.4 прил. А ГОСТ 33670-2015 | B11: При проверках на стендах допускается относительная разность тормозных сил колес оси (в процентах от наибольшего значения) для осей ТС с дисковыми колесными тормозными механизмами не более 20% и для осей с барабанными колесными тормозными механизмами не более 25% | H11: Дисковые/дисковые
H12: Дисковые/барабанные
H13: Ось 1 | I13: Ось 2
B14: Относительная разность тормозных сил колес оси | H14: 0 | I14: 15 | J14: % | S14: 0 | T14: 25
A15: п. А 5.1.4.1.1 прил. А ГОСТ 33670-2015 | B15: Удельная тормозная сила для стояночной тормозной системы | S15: 0.17 | T15: 0.3
E16: ось 1 | F16: Левое колесо | I16: 2790 | J16: Н
F17: Правое колесо | I17: 2800 | J17: Н | K17: =(I17-I16)/I17 -> 0.0035714286 | L17: =(MAX(I16:I17)-MIN(I16:I17))/MAX(I16:I17) -> 0.0035714286
E18: ось 2 | F18: Левое колесо | I18: 2000 | J18: Н
F19: Правое колесо | I19: 2450 | J19: Н | K19: =(I19-I18)/I19 -> 0.18367347 | L19: =(MAX(I18:I19)-MIN(I18:I19))/MAX(I18:I19) -> 0.18367347
D20: Стояночная | F20: Левое колесо | I20: 2150 | J20: Н
F21: Правое колесо | I21: 1950 | J21: Н
A22: п. А 5.1.5 прил. АГОСТ 33670-2015 | B22: Усилие, прикладываемое к органу управления стояночной тормозной системой для приведения ее в действие, не должно превышать: - 589 Н - в случае ручного органа управления; - 688 Н - в случае ножного органа управления | H22: 490 | J22: Н | S22: 0 | T22: 568
A23: п. А 5 прил. А ГОСТ 33670-2015 | B23: Нагрузка на оси. | H23: Ось 1 | I23: Ось 2
H24: 995 | I24: 850
A25: п. А.8.9 прил. А ГОСТ 33670-2015 | B25: Требования к размещению фар ближнего света: по высоте над опорной поверхностью - не менее 500 мм, не более 1200 мм | H25: Левая | I25: Правая
H26: нижняя граница:
H27: 630 | I27: 630 | S27: 502 | T27: 1198
H28: верхняя граница:
H29: 780 | I29: 780 | S29: 502 | T29: 1198
A30: п. А.8.10.1 прил. А ГОСТ 33670-2015 | B30: Требования к размещению передних противотуманных фар. По ширине: та точка видимой поверхности в направлении исходной оси, которая в наибольшей степени удалена от средней продольной плоскости ТС, должна находиться на расстоянии не более 400 мм от края габаритной ширины ТС | H30: Левая | I30: Правая
H31: 100 | I31: 100 | S31: 0 | T31: 398
A32: п. А.8.10.2 прил. А ГОСТ 33670-2015 | B32: Требования к размещению передних противотуманных фар. По высоте: не менее 250 мм над поверхностью земли; для ТС категорий M1 и N1 - не более 800 мм над опорной поверхностью; для всех других категорий ТС максимальная высота не предусмотрена | H32: Левая | I32: Правая
H33: нижняя граница:
H34: 260 | I34: 260 | S34: 252 | T34: 798
H35: верхняя граница:
H36: 280 | I36: 280 | S36: 252 | T36: 798
A37: п. А.8.12.1 прил. А ГОСТ 33670-2015 | B37: Требования к размещению сигналов торможения: по ширине: для ТС категорий M1, N1, L2, L4 - L7 та точка видимой поверхности в направлении исходной оси, которая в наибольшей степени удалена от средней продольной плоскости ТС, должна находиться на расстоянии не более 400 мм от края габаритной ширины ТС; для ТС категорий L2, L5 - L7 в случае установки одного сигнала торможения его исходная ось должна лежать в средней продольной плоскости ТС, для ТС категории L4, если устанавливается третий сигнал торможения, то он должен быть установлен симметрично сигналу торможения, установленному на мотоцикле относительно средней продольной плоскости мотоцикла; для всех других категорий ТС та точка видимой поверхности в направлении исходной оси, которая в наименьшей степени удалена от средней продольной плоскости ТС, должна находиться на расстоянии не менее 600 мм от края габаритной ширины ТС. Это расстояние может быть уменьшено до 400 мм, если габаритная ширина ТС составляет менее 1300 мм | H37: Левая | I37: Правая
H38: 150 | I38: 150 | S38: 0 | T38: 400
H39: На кузове | J39: на Багажнике
A40: п. А.8.12.2 прил. А ГОСТ 33670-2015 | B40: Требования к размещению сигналов торможения: по высоте: над опорной поверхностью в пределах от 350 до 1500 мм (не менее 2100 мм, если соблюдение указанного требования невозможно из-за формы кузова, если факультативные огни не установлены). Если факультативные огни установлены, то они должны располагаться симметрично на как можно большем расстоянии по вертикали, которое допускается контуром кузова, но не менее чем 600 мм над обязательными огнями (кроме ТС категорий L). Для ТС категорий L1 - L3, L5 - L7 - не менее 250 мм и не более 1500 мм над опорной поверхностью; для ТС категории L4 - не менее 250 мм, не более 1200 мм над опорной поверхностью | H40: Левая | I40: Правая | J40: Левая | K40: Правая
...

Sheet Правило
I3: Общество с ограниченной ответственностью «А-Профит»
I4: (ООО «А-Профит»)
I5: Адрес места нахождения юридического лица:
I6: 690074, Россия, Приморский край, г. Владивосток, ул. Снеговая, д. 64, офис 1
I7: Тел.: 89240037850, e-mail: a_profit_lab@mail.ru
I9: Испытательная лаборатория ООО «А-Профит»
I10: (ООО «А-Профит»)
I11: Адреса мест осуществления деятельности:
I12: 690074, Россия, Приморский край, г. Владивосток, ул. Снеговая, д. 64
I13: Тел.: 89240037850, e-mail: a_profit_lab@mail.ru
M16: УТВЕРЖДАЮ
M18: Руководитель ИЛ ООО «А-Профит»
O19: А.Г. Луговой
M20: Подпись | O20: И.О. Фамилия
M21: =M28 -> 08.05.2025 г.
G28: Протокол № | I28: АВМ00 | K28: от | M28: 08.05.2025 г.
C29: идентификации, технической экспертизы конструкции, исследований, испытаний и измерений транспортного средства на соответствия предъявляемым требованиям ТР ТС 018/2011 к Единичным транспортным средствам
H73: Результаты исследований, испытаний и измерений относятся только к образцу (объекту), предоставленному заказчиком.
H74: Результаты исследований, испытаний и измерений относятся только к образцу (объекту), прошедшему исследования,
H75: испытания и измерения в испытательной лаборатории ООО «А-Профит».
H76: Протокол не может быть частично воспроизведен без письменного разрешения лаборатории.
H77: Испытательная лаборатория (центр) несет ответственность за всю информацию, предоставленную в протоколе
H78: испытаний, за исключением случаев, когда информация предоставлена заказчиком.
A80: Протокол идентификации, технической экспертизы конструкции, исследований, испытаний и измерений транспортного средства на соответствия предъявляемым требованиям
E81: ТР ТС 018/2011 к Единичным транспортным средствам № | J81: =I28 -> АВМ00 | L81: от | M81: =M28 -> 08.05.2025 г.
I83: 1. ОБЪЕКТ ИСПЫТАНИЙ
B84: Таблица 1.1 Общие сведения
A85: Наименование образца испытаний (идентификация объекта, поступившего на испытания: марка, тип/обозначение, заводской номер, другая уникальная идентифицирующая информация) | F85: Транспортное средство:
F86: Марка | K86: HAVAL
F87: коммерческое название | K87: F7
F88: тип | K88: CC6475UM22B
F89: Индефикационный номер (VIN) | K89: XZGFF06A9PA346000
F90: Гос. Номер
F91: Категория | K91: М1
A92: Наименование и контактные данные заказчика* (для юридических лиц указывают наименование, юридический адрес и фактический адрес места осуществления деятельности; для ИП указывают инициалы, фамилию, адрес регистрации; для физического лица указывают инициалы, фамилию, почтовый адрес) | F92: ООО «А-Профит» Адрес места нахождения юридического лица: 690074, Россия, Приморский край, г. Владивосток, ул. Снеговая, д. 64, офис 1 Адреса мест осуществления деятельности: 690074, Россия, Приморский край, г. Владивосток, ул. Снеговая, д. 64
A97: Наименование и адрес изготовителя (юридический адрес и фактический адрес места осуществления деятельности) | F97: Изготовитель и его адрес: ООО "ХАВЕЙЛ МОТОР МАНУФЭКЧУРИНГ РУС" Адрес: г. Москва, Профсоюзная улица, д. 65, корпус 1 Сборочный завод и его адрес: Завод HAVAL Адрес: 301637, Российская Федерация, Тульская область, Узловский Район, ул. Индустриальная (Индустриальный парк тер.), здание 11
A100: Данные об отборе образца | F100: Образец предоставлен заказчиком, ИЛ не несет ответственности за данные отбора образца
A102: Дата получения образца | F102: =M28 -> 08.05.2025 г.
A103: Дата(ы) начала и окончания испытаний | F103: =M28 -> 08.05.2025 г.
A104: Цель осуществления проведения испытаний | F104: Оценка соответствия определяемых в рамках испытаний характеристик единичного транспортного средства требованиям TP TC 018/2011
...

Sheet Оборудование
A1: Текущая дата | C1: =TODAY() -> 46310 | E1: TRUE
H2: 3. СВЕДЕНИЯ О ПРИМЕНЯЕМОМ ОБОРУДОВАНИИ
A3: Средства измерения
A4: № п/п | B4: Наименование испытательного оборудования, средств измерения | D4: Диапазон измерений | F4: Класс точности (разряд), погрешность | M4: Сведения о результатах поверки СИ (дата, срок действия) | Q4: Заводской или инвентарный номер
A5: 1 | B5: Измеритель параметров света фар автотранспортных средств ИПФ-01 | D5: от 0 до 2° 20’ (угол наклона) от 200 до 125000 кД (сила света) от 1 до 2Гц (частота проблесков) | F5: Абсолютная погрешность измерения углов наклона светотеневой границы светового пучка фары в вертикальной плоскости: ±0,1% Абсолютная погрешность установки оптической камеры измерителя в горизонтальной плоскости: ±30 ' Относительная погрешность измерения силы света внешних световых источников: ±15% Абсолютная погрешность измерения частоты следования световых проблесков фонарей указателей поворота: ±0,1 Гц | M5: Св-во № С-АЭ/06-08-2025/ 453157456 от | Q5: № СИ001
M6: 45875 | O6: г., 12 мес.
A7: 2 | B7: Преобразователь измерительный угла поворота «ИСЛ-М» | D7: от 0 до 50° | F7: Максимальная погрешность измерения суммарного люфта: ±0,5° | M7: Св-во № С-АЭ/02-06-2025/ 436547222 от | Q7: № СИ002
M8: 45810 | O8: г., 12 мес.
A9: 3 | B9: Дымомер АВГ-1Д-4.01 | D9: от 0,00 до ∞ от 0,0 до 100,0% от 0 до 6000 мин 0 до +100°С | F9: абсолютная погрешность при коэффициенте поглощения 1,6-1,8м-1: ±0,05 Погрешность: ±1,0 % Погрешность: ±2,5 % Погрешность: ±2,5 % | M9: Св-во № С-АЭ/02-06-2025/ 436579464 от | Q9: № СИ003
M10: 45810 | O10: г., 12 мес.
A11: 4 | B11: Измеритель светопропускания стекол "ТОНИК" | D11: от 4 до 100% | F11: Абсолютная погрешность ±2,0% | M11: Св-во № С-АЭ/06-08-2025/ 453155401 от | Q11: № СИ004
M12: 45875 | O12: г., 12 мес.
A13: 5 | B13: Газоанализатор многокомпонентный «Автотест-02.02» 0 кл | D13: Углеводороды от 0 до 2000 млн1 оксид углерода от 0 до 5%, диоксид углерода от 0 до 16%, кислород от 0 до 21%, окислы азота от 0 до 5000 млн1 λ-параметр 0,5-2,00 частота оборотов от 0-8000 мин1 температура масла от 0 до 125°С | F13: Абсолютная погрешность: ±10млн1, относительная погрешность: ±5% Абсолютная погрешность: ±0,03%, относительная погрешность: ±3% Абсолютная погрешность: ±0,5%, относительная погрешность: ±4% Абсолютная погрешность: ±0,1%, относительная погрешность: ±3% Абсолютная погрешность: ±50млн1, относительная погрешность: ±5% Не нормируется Относительная погрешность: ±2,5% Абсолютная погрешность: ±2°С | M13: Св-во № С-АЭ/10-07-2025/ 446406612 от | Q13: № СИ005
M14: 45848 | O14: г., 12 мес.
A15: 6 | B15: Стенд тормозной СТН 13000.01 | D15: от 0 до 30 кН (тормозная сила) от 0 до 1000Н (сила на органе управления) от 0 до 13000кг (масса ТС) | F15: Относительная погрешность: ±3% (тормозная сила) ±5% (сила на органе управления) ±3% (масса ТС) | M15: Св-во№ С-АЭ/05-09-2025/ 461489585 от | Q15: № СИ006
M16: 45905 | O16: г., 12 мес.
A17: 7 | B17: Рулетка Р30У2К 30м | D17: от 0 до 30м | F17: Класс 2 Допускаемое отклонение: мм±0,15, см±0,20, дц±0,30, м ±[0,30+0,15(L-l)] | M17: Св-во № С-АЭ/05-09-2025/ 461447340 от | Q17: № СИ007
M18: 45905 | O18: г., 12 мес.
A19: 8 | B19: Штангенциркуль ШЦ-1-150 0,05 | D19: от 0 до 100мм | F19: Погрешность показаний: ±0,05мм | M19: Св-во № С-АЭ/02-06-2025/ 436547220 от | Q19: № СИ008
M20: 45810 | O20: г., 12 мес.
A21: 9 | B21: Угломер маятниковый З УРИ-М | D21: от 0 до 360° | F21: Погрешность показаний: ±1º | M21: Св-во № С-АЭ/21-08-2025/ 458005858 от | Q21: № СИ009
M22: 45890 | O22: г., 12 мес.
A23: 10 | B23: Прибор комбинированный Testo 622 | D23: от-10 до +60 °С от 10 до 95 % от 30 до 120 кПа | F23: Погрешность: ±0,4 °С ±3 % ±0,5 кПа | M23: Св-во № С-ВЦЛ/01-09-2025/ 460740052 от | Q23: № СИ010
M24: 45901 | O24: г., 12 мес.
A25: 11 | B25: Термометр инфракрасный Testo 830-Т 1 | D25: от -30 до +400°C | F25: Погрешность показаний: ±1,5°C (от +0,1 до +400°C) ±2,0°C (от -30 до 0°C) | M25: Св-во № С-АЭ/19-08-2025/ 457455641 от | Q25: № СИ011
M26: 45888 | O26: г., 12 мес.
A27: 12 | B27: Измеритель скорости и длины ИСД-5.1 | D27: от 0,5 до 180 км/ч | F27: Пределы допускаемой относительной среднеквадратичной погрешности измерения скорости ±0,15% и длины ±0,1% - на длине не менее 20 м | M27: Св-во № С-С/15-10-2025/474327055 от | Q27: № СИ013
M28: 45945 | O28: г., 12 мес.
A29: 13 | B29: Шумомер-анализатор спектра портативный ОКТАВА-111 + микрофонный предусилитель Р200 | D29: от 19 до 141дБ | F29: Класс 1 Погрешность показаний: ±0,5 дБ | M29: Св-во № С-АЭ/19-08-2025/ 457406029 от | Q29: № СИ014
M30: 45888 | O30: г., 12 мес.
A31: 14 | B31: Калибратор акустический AK-1000 | D31: 1000 Гц в режиме основного тона, 94,0 и 114,0 дБ относительно 20 мкПа 114,0 Основной уровень | F31: Класс 1 Погрешность показаний: ±0,5 дБ Предел допускаемой абсолютной погрешности при нормальных условиях ±0,25 дБ Предел допускаемой дополнительной погрешности, вызванной изменением температуры ±0,08 дБ Пределы отклонения уровня звукового давления при изменениях напряжения электропитания ±0,07дБ | M31: Св-во № С-АЭ/08-09-2025/ 461980384 от | Q31: № СИ015
M32: 45908 | O32: г., 12 мес.
A33: 15 | B33: Динамометр электронный АЦД/1У-0,5/1И-1 | D33: от 0,05 до 0,5кН | F33: Погрешность показаний ±0,24% | M33: С-во № С-АЭ/21-08-2025/ 458005861 от | Q33: № СИ016
M34: 45890 | O34: г., 12 мес.
A35: 16 | B35: Весы автомобильные подкладные ИСТОК-30-4П/10кг | D35: от 200 до 30000кг | F35: Пределы допускаемой погрешности: от 200 до 5000 вкл. кг ± 5 кг св. 5000 до 20000 вкл. кг ±10кг св. 20000 до 30000 вкл. кг ±15кг) | M35: Св-во № С-АЭ/05-09-2025/ 461489581 от | Q35: № СИ018
M36: 45905 | O36: г., 12 мес.
A37: 17 | B37: Весы неавтоматического действия МП150 ВДА Ф-3 | D37: от 0,04 кг до 150 кг | F37: Класс 3 Допустимое отклонение: 0,01 кг | M37: Св-во № С-АЭ/14-01-2026/ 494028488 от | Q37: № СИ019
M38: 46036 | O38: г., 12 мес.
A39: 18 | B39: Угломер с нониусом 4УМ | D39: от 0 до 180° | F39: Погрешность показаний: ± 0,10´ | M39: Св-во № С-АЭ/21-08-2025/ 458005859 от | Q39: № СИ020
M40: 45890 | O40: г., 12 мес.
...

Sheet Лист оценки
B1: Лист оценки неопределенности к протоколу № АТ04 от 12.09.2025 г.
B2: Методика | C2: Определяемая характеристика | D2: Единицы измерения | E2: Используемое оборудование | G2: Количество контрольных процедур (измерений) | H2: Результаты измерений: Х1 – если одно измерение, Хn если несколько измерений | I2: Расчет неопределенности
E3: Наименование оборудования, зав./инв. № | F3: Погрешность (применимая для расчета неопределённости) | H3: X1 | I3: Неопределенность по типу А, UA | J3: Неопределенность по типу B, UB | K3: Суммарная стандартная неопределенность, uc | L3: Расширенная неопределенность (при Р=95%, k=1,65 u | M3: Примечание
B4: п.А.1.2.2 Приложения А, ГОСТ 33670-2015 | C4: Угол между плоскостью переднего государственного регистрационного знака и продольной плоскостью симметрии ТС | D4: Градусы, ° | E4: Угломер с нониусом Micron, модификация УНЛ-360 Зав. № 4-24020385 Инв. № СИ036 | F4: ± 5' | G4: 1 | H4: =Расчет!O55 -> 90 | I4: 0 | J4: =Расчет!D30 -> 0.048112522 | K4: =Расчет!F40 -> 0.048112522 | L4: =Расчет!Q55 -> 0.079385662
B5: п.А.1.2.2 Приложения А, ГОСТ 33670-2015 | C5: Угол между плоскостью заднего государственного регистрационного знака и продольной плоскостью симметрии ТС | D5: Градусы, ° | E5: Угломер с нониусом Micron, модификация УНЛ-360 Зав. № 4-24020385 Инв. № СИ036 | F5: ± 5' | G5: 1 | H5: =Расчет!O56 -> 90 | I5: 0 | J5: =Расчет!D30 -> 0.048112522 | K5: =Расчет!F46 -> 0.048112522 | L5: =Расчет!Q56 -> 0.079385662
B6: п.А.1.2.2 Приложения А, ГОСТ 33670-2015 | C6: Угол между плоскостью переднего государственного регистрационного знака и опорной поверхностью | D6: Градусы, ° | E6: Угломер маятниковый З УРИ-М Зав. № 9405 Инв. № СИ009 | F6: ±1° | G6: 1 | H6: =Расчет!N95 -> 90 | I6: 0 | J6: =Расчет!D68 -> 0.57735027 | K6: =Расчет!F81 -> 0.57735027 | L6: =Расчет!P95 -> 0.95262794
B7: п.А.1.2.2 Приложения А, ГОСТ 33670-2015 | C7: Угол между плоскостью заднего государственного регистрационного знака и опорной поверхностью | D7: Градусы, ° | E7: Угломер маятниковый З УРИ-М Зав. № 9405 Инв. № СИ009 | F7: ±1° | G7: 1 | H7: =Расчет!N96 -> 90 | I7: 0 | J7: =Расчет!D68 -> 0.57735027 | K7: =Расчет!F87 -> 0.57735027 | L7: =Расчет!P96 -> 0.95262794
B8: п.А.1.2.2, п.А.1.2.3 Приложения А, ГОСТ 33670-2015 | C8: Высота от опорной плоскости верхнего края переднего государственного регистрационного знака | D8: миллиметры, мм | E8: Рулетка RGK R-5 Зав. № 2438 Инв. № СИ035 | F8: ±0,3 мм | G8: 1 | H8: =Расчет!N166 -> 302 | I8: 0 | J8: =Расчет!E116 -> 0.11547005 | K8: =Расчет!C123 -> 0.17320508 | L8: =Расчет!P166 -> 0.28578838
B9: п.А.1.2.2, п.А.1.2.3 Приложения А, ГОСТ 33670-2015 | C9: Высота от опорной плоскости верхнего края заднего государственного регистрационного знака | D9: миллиметры, мм | E9: Рулетка RGK R-5 Зав. № 2438 Инв. № СИ035 | F9: ±0,3 мм | G9: 1 | H9: =Расчет!N167 -> 600 | I9: 0 | J9: =Расчет!E116 -> 0.11547005 | K9: =Расчет!C125 -> 0.17320508 | L9: =Расчет!P167 -> 0.28578838
B10: п.А.1.2.3 Приложения А, ГОСТ 33670-2015 | C10: Высота от опорной плоскости нижнего края переднего государственного регистрационного знака | D10: миллиметры, мм | E10: Рулетка RGK R-5 Зав. № 2438 Инв. № СИ035 | F10: ±0,3 мм | G10: 1 | H10: =Расчет!N168 -> 500 | I10: 0 | J10: =Расчет!E116 -> 0.11547005 | K10: =Расчет!C127 -> 0.17320508 | L10: =Расчет!P168 -> 0.28578838
B11: п.А.1.2.3 Приложения А, ГОСТ 33670-2015 | C11: Высота от опорной плоскости нижнего края заднего государственного регистрационного знака | D11: миллиметры, мм | E11: Рулетка RGK R-5 Зав. № 2438 Инв. № СИ035 | F11: ±0,3 мм | G11: 1 | H11: =Расчет!N169 -> 500 | I11: 0 | J11: =Расчет!E116 -> 0.11547005 | K11: =Расчет!C129 -> 0.17320508 | L11: =Расчет!P169 -> 0.28578838
B12: п.А.5.1.1.3 Приложения А, ГОСТ 33670-2015 | C12: Усилие на органе управления рабочей тормозной системы 1 Оси | D12: Ньютон, Н | E12: Стенд тормозной СТН 13000.01 Зав. № 507 Инв. № СИ006 | F12: Относительная ± 5% | G12: 1 | H12: =Расчет!L266 -> 490 | I12: 0 | J12: =Расчет!E217 -> 14.148027 | K12: =Расчет!F241 -> 14.148027 | L12: =Расчет!N266 -> 23.344244
B13: п.А.5.1.1.3 Приложения А, ГОСТ 33670-2015 | C13: Усилие на органе управления рабочей тормозной системы 2 Оси | D13: Ньютон, Н | E13: Стенд тормозной СТН 13000.01 Зав. № 507 Инв. № СИ006 | F13: Относительная ± 5% | G13: 1 | H13: =Расчет!L267 -> 490 | I13: 0 | J13: =Расчет!E224 -> 14.148027 | K13: =Расчет!F247 -> 14.148027 | L13: =Расчет!N267 -> 23.344244
B14: п.А.5.1.5 Приложения А, ГОСТ 33670-2015 | C14: Усилие на органе управления стояночной тормозной системы | D14: Ньютон, Н | E14: Стенд тормозной СТН 13000.01 Зав. № 507 Инв. № СИ006 | F14: Относительная ± 5% | G14: 1 | H14: =Расчет!L268 -> 490 | I14: 0 | J14: =Расчет!E231 -> 14.148027 | K14: =Расчет!F253 -> 14.148027 | L14: =Расчет!N268 -> 23.344244
B15: п.А.5.1.1.4, А.5.9 Приложения А, ГОСТ 33670-2015 | C15: Относительная разности тормозных сил колес 1 оси | D15: Проценты, % | E15: Стенд тормозной СТН 13000.01 Зав. № 507 Инв. № СИ006 | F15: Относительная ± 3% | G15: 1 | H15: =Расчет!I545 -> 0 | I15: 0 | J15: - | K15: =Расчет!F530 -> 2.4582579 | L15: =Расчет!K545 -> 4.0561256
B16: п.А.5.1.1.4, А.5.9 Приложения А, ГОСТ 33670-2015 | C16: Относительная разности тормозных сил колес 2 оси | D16: Проценты, % | E16: Стенд тормозной СТН 13000.01 Зав. № 507 Инв. № СИ006 | F16: Относительная ± 3% | G16: 1 | H16: =Расчет!I546 -> 15 | I16: 0 | J16: - | K16: =Расчет!F536 -> 3.0092933 | L16: =Расчет!K546 -> 4.965334
B17: п.А.5.1.1.3, п.А.5.9 Приложения А, ГОСТ 33670-2015 | C17: Удельная тормозная сила рабочей тормозной системы | D17: Безразмерная величина | E17: Стенд тормозной СТН 13000.01 Зав. № 507 Инв. № СИ006 | F17: Относительная ± 3% | G17: 1 | H17: =Расчет!J443 -> 0.55527902 | I17: 0 | J17: - | K17: =Расчет!F420 -> 0.010776185 | L17: =Расчет!L443 -> 0.017780705
B18: п.А.5.1.4.1.1, п.А.5,9 Приложения А, ГОСТ 33670-2015 | C18: Удельная тормозная сила стояночной тормозной системы | D18: Безразмерная величина | E18: Стенд тормозной СТН 13000.01 Зав. № 507 Инв. № СИ006 | F18: Относительная ± 3% | G18: 1 | H18: =Расчет!J444 -> 0.22675737 | I18: 0 | J18: - | K18: =Расчет!F428 -> 0.0048175823 | L18: =Расчет!L444 -> 0.0079490108
B19: п.А.5 Приложения А, ГОСТ 33670-2015 | C19: Нагрузка на 1 ось | D19: Килограммы, кг | E19: Стенд тормозной СТН 13000.01 Зав. № 507 Инв. № СИ006 | F19: Относительная ± 3% | G19: 1 | H19: =Расчет!H615 -> 995 | I19: 0 | J19: =Расчет!E570 -> 17.233906 | K19: =Расчет!C581 -> 17.233906 | L19: =Расчет!J615 -> 28.435944
B20: п.А.5 Приложения А, ГОСТ 33670-2015 | C20: Нагрузка на 2 ось | D20: Килограммы, кг | E20: Стенд тормозной СТН 13000.01 Зав. № 507 Инв. № СИ006 | F20: Относительная ± 3% | G20: 1 | H20: =Расчет!H616 -> 850 | I20: 0 | J20: =Расчет!E576 -> 14.722432 | K20: =Расчет!C583 -> 14.722432 | L20: =Расчет!J616 -> 24.292013
B21: п.А.8.9 Приложения А, ГОСТ 33670-2015 | C21: Высота нижней границы размещения левой фары ближнего света над опорной поверхностью | D21: миллиметры, мм | E21: Рулетка RGK R-5 Зав. № 2438 Инв. № СИ035 | F21: ±0,3 мм | G21: 1 | H21: =Расчет!O908 -> 630 | I21: 0 | J21: =Расчет!E665 -> 0.17320508 | K21: =Расчет!C672 -> 0.17320508 | L21: =Расчет!Q908 -> 0.28578838
B22: п.А.8.9 Приложения А, ГОСТ 33670-2015 | C22: Высота нижней границы размещения правой фары ближнего света над опорной поверхностью | D22: миллиметры, мм | E22: Рулетка RGK R-5 Зав. № 2438 Инв. № СИ035 | F22: ±0,3 мм | G22: 1 | H22: =Расчет!O909 -> 630 | I22: 0 | J22: =Расчет!E665 -> 0.17320508 | K22: =Расчет!C674 -> 0.17320508 | L22: =Расчет!Q909 -> 0.28578838
B23: п.А.8.9 Приложения А, ГОСТ 33670-2015 | C23: Высота верхней границы размещения левой фары ближнего света над опорной поверхностью | D23: миллиметры, мм | E23: Рулетка RGK R-5 Зав. № 2438 Инв. № СИ035 | F23: ±0,3 мм | G23: 1 | H23: =Расчет!O910 -> 780 | I23: 0 | J23: =Расчет!E665 -> 0.17320508 | K23: =Расчет!C676 -> 0.17320508 | L23: =Расчет!Q910 -> 0.28578838
B24: п.А.8.9 Приложения А, ГОСТ 33670-2015 | C24: Высота верхней границы размещения правой фары ближнего света над опорной поверхностью | D24: миллиметры, мм | E24: Рулетка RGK R-5 Зав. № 2438 Инв. № СИ035 | F24: ±0,3 мм | G24: 1 | H24: =Расчет!O911 -> 780 | I24: 0 | J24: =Расчет!E665 -> 0.17320508 | K24: =Расчет!C678 -> 0.17320508 | L24: =Расчет!Q911 -> 0.28578838
B25: п. А.8.10.1 Приложения А ГОСТ 33670-2015 | C25: Точка видимой поверхности в направлении исходной оси, которая в наибольшей степени удалена от средней продольной плоскости ТС от края габаритной ширины ТС передней левой противотуманной фары | D25: миллиметры, мм | E25: Рулетка RGK R-5 Зав. № 2438 Инв. № СИ035 | F25: ±0,3 мм | G25: 1 | H25: =Расчет!O912 -> 100 | I25: 0 | J25: =Расчет!E665 -> 0.17320508 | K25: =Расчет!C680 -> 0.17320508 | L25: =Расчет!Q912 -> 0.28578838 | N25: Наличие отсутствие противотуманок передних
B26: п. А.8.10.1 Приложения А ГОСТ 33670-2015 | C26: Точка видимой поверхности в направлении исходной оси, которая в наибольшей степени удалена от средней продольной плоскости ТС от края габаритной ширины ТС передней правой противотуманной фары | D26: миллиметры, мм | E26: Рулетка RGK R-5 Зав. № 2438 Инв. № СИ035 | F26: ±0,3 мм | G26: 1 | H26: =Расчет!O913 -> 100 | I26: 0 | J26: =Расчет!E665 -> 0.17320508 | K26: =Расчет!C682 -> 0.17320508 | L26: =Расчет!Q913 -> 0.28578838
B27: п. А.8.10.2 Приложения А ГОСТ 33670-2015 | C27: Расстояние от нижней точки левой передней противотуманной фары до опорной поверхности | D27: миллиметры, мм | E27: Рулетка RGK R-5 Зав. № 2438 Инв. № СИ035 | F27: ±0,3 мм | G27: 1 | H27: =Расчет!O914 -> 260 | I27: 0 | J27: =Расчет!E665 -> 0.17320508 | K27: =Расчет!C684 -> 0.17320508 | L27: =Расчет!Q914 -> 0.28578838
B28: п. А.8.10.2 Приложения А ГОСТ 33670-2015 | C28: Расстояние от нижней точки правой передней противотуманной фары до опорной поверхности | D28: миллиметры, мм | E28: Рулетка RGK R-5 Зав. № 2438 Инв. № СИ035 | F28: ±0,3 мм | G28: 1 | H28: =Расчет!O915 -> 260 | I28: 0 | J28: =Расчет!E665 -> 0.17320508 | K28: =Расчет!C686 -> 0.17320508 | L28: =Расчет!Q915 -> 0.28578838
B29: п. А.8.10.2 Приложения А ГОСТ 33670-2015 | C29: Расстояние от верхней точки левой передней противотуманной фары до опорной поверхности | D29: миллиметры, мм | E29: Рулетка RGK R-5 Зав. № 2438 Инв. № СИ035 | F29: ±0,3 мм | G29: 1 | H29: =Расчет!O916 -> 280 | I29: 0 | J29: =Расчет!E665 -> 0.17320508 | K29: =Расчет!C688 -> 0.17320508 | L29: =Расчет!Q916 -> 0.28578838
B30: п. А.8.10.2 Приложения А ГОСТ 33670-2015 | C30: Расстояние от верхней точки правой передней противотуманной фары до опорной поверхности | D30: миллиметры, мм | E30: Рулетка RGK R-5 Зав. № 2438 Инв. № СИ035 | F30: ±0,3 мм | G30: 1 | H30: =Расчет!O917 -> 280 | I30: 0 | J30: =Расчет!E665 -> 0.17320508 | K30: =Расчет!C690 -> 0.17320508 | L30: =Расчет!Q917 -> 0.28578838
B31: п.А.8.12.1 Приложения А, ГОСТ 33670-2015 | C31: Расстояние от точки видимой поверхности левого сигнала торможения в направлении исходной оси, которая в наибольшей степени удалена от средней продольной плоскости ТС до края габаритной ширины ТС | D31: миллиметры, мм | E31: Рулетка RGK R-5 Зав. № 2438 Инв. № СИ035 | F31: ±0,3 мм | G31: 1 | H31: =Расчет!O918 -> 150 | I31: 0 | J31: =Расчет!E665 -> 0.17320508 | K31: =J31 -> 0.17320508 | L31: =Расчет!Q918 -> 0.28578838
B32: п.А.8.12.1 Приложения А, ГОСТ 33670-2015 | C32: Расстояние от точки видимой поверхности правого сигнала торможения в направлении исходной оси, которая в наибольшей степени удалена от средней продольной плоскости ТС до края габаритной ширины ТС | D32: миллиметры, мм | E32: Рулетка RGK R-5 Зав. № 2438 Инв. № СИ035 | F32: ±0,3 мм | G32: 1 | H32: =Расчет!O919 -> 150 | I32: 0 | J32: =Расчет!E665 -> 0.17320508 | K32: =J32 -> 0.17320508 | L32: =Расчет!Q919 -> 0.28578838
B33: п.А.8.12.2 Приложения А, ГОСТ 33670-2015 | C33: Расстояние от нижней точки левого сигнала торможения на кузове до опорной поверхности | D33: миллиметры, мм | E33: Рулетка RGK R-5 Зав. № 2438 Инв. № СИ035 | F33: ±0,3 мм | G33: 1 | H33: =Расчет!O920 -> 890 | I33: 0 | J33: =Расчет!E665 -> 0.17320508 | K33: =J33 -> 0.17320508 | L33: =Расчет!Q920 -> 0.28578838 | N33: На каких то машинах только кузов, а где то и багажник и кузов
B34: п.А.8.12.2 Приложения А, ГОСТ 33670-2015 | C34: Расстояние от нижней точки правого сигнала торможения на кузове до опорной поверхности | D34: миллиметры, мм | E34: Рулетка RGK R-5 Зав. № 2438 Инв. № СИ035 | F34: ±0,3 мм | G34: 1 | H34: =Расчет!O921 -> 890 | I34: 0 | J34: =Расчет!E665 -> 0.17320508 | K34: =J34 -> 0.17320508 | L34: =Расчет!Q921 -> 0.28578838
B35: п.А.8.12.2 Приложения А, ГОСТ 33670-2015 | C35: Расстояние от верхней точки левого сигнала торможения на кузове до опорной поверхности | D35: миллиметры, мм | E35: Рулетка RGK R-5 Зав. № 2438 Инв. № СИ035 | F35: ±0,3 мм | G35: 1 | H35: =Расчет!O922 -> 955 | I35: 0 | J35: =Расчет!E665 -> 0.17320508 | K35: =J35 -> 0.17320508 | L35: =Расчет!Q922 -> 0.28578838
B36: п.А.8.12.2 Приложения А, ГОСТ 33670-2015 | C36: Расстояние от верхней точки правого сигнала торможения на кузове до опорной поверхности | D36: миллиметры, мм | E36: Рулетка RGK R-5 Зав. № 2438 Инв. № СИ035 | F36: ±0,3 мм | G36: 1 | H36: =Расчет!O923 -> 955 | I36: 0 | J36: =Расчет!E665 -> 0.17320508 | K36: =J36 -> 0.17320508 | L36: =Расчет!Q923 -> 0.28578838
B37: п.А.8.12.2 Приложения А, ГОСТ 33670-2015 | C37: Расстояние от нижней точки левого сигнала торможения на крышке багажника до опорной поверхности | D37: миллиметры, мм | E37: Рулетка RGK R-5 Зав. № 2438 Инв. № СИ035 | F37: ±0,3 мм | G37: 1 | H37: =Расчет!O924 -> 860 | I37: 0 | J37: =Расчет!E665 -> 0.17320508 | K37: =J37 -> 0.17320508 | L37: =Расчет!Q924 -> 0.28578838
B38: п.А.8.12.2 Приложения А, ГОСТ 33670-2015 | C38: Расстояние от нижней точки правого сигнала торможения на крышке багажника до опорной поверхности | D38: миллиметры, мм | E38: Рулетка RGK R-5 Зав. № 2438 Инв. № СИ035 | F38: ±0,3 мм | G38: 1 | H38: =Расчет!O925 -> 865 | I38: 0 | J38: =Расчет!E665 -> 0.17320508 | K38: =J38 -> 0.17320508 | L38: =Расчет!Q925 -> 0.28578838
B39: п.А.8.12.2 Приложения А, ГОСТ 33670-2015 | C39: Расстояние от верхней точки левого сигнала торможения на крышке багажника до опорной поверхности | D39: миллиметры, мм | E39: Рулетка RGK R-5 Зав. № 2438 Инв. № СИ035 | F39: ±0,3 мм | G39: 1 | H39: =Расчет!O926 -> 935 | I39: 0 | J39: =Расчет!E665 -> 0.17320508 | K39: =J39 -> 0.17320508 | L39: =Расчет!Q926 -> 0.28578838
B40: п.А.8.12.2 Приложения А, ГОСТ 33670-2015 | C40: Расстояние от верхней точки правого сигнала торможения на крышке багажника до опорной поверхности | D40: миллиметры, мм | E40: Рулетка RGK R-5 Зав. № 2438 Инв. № СИ035 | F40: ±0,3 мм | G40: 1 | H40: =Расчет!O927 -> 940 | I40: 0 | J40: =Расчет!E665 -> 0.17320508 | K40: =J40 -> 0.17320508 | L40: =Расчет!Q927 -> 0.28578838
...
